Workbook

Sheet Légende
A1: Base de données Cuisine — addon WoW Forever
A3: Onglets
A4: Recettes : une ligne par recette (niveaux orange/jaune/vert/gris, appris chez un maître ou non).
A5: Composants : lien recette ↔ ingrédient avec la quantité (clé de jointure : id_recette, id_ingrédient).
A6: Ingrédients : liste unique des ingrédients, avec le nombre de recettes qui les utilisent (formule).
A7: Sources : où trouver chaque ingrédient (monstre, pêche, vendeur), une ligne par ingrédient et par zone. Rempli à partir de Wowhead Classic ; lignes jaunes libres pour compléter.
A8: Marchands : marchands de composants relevés en jeu par l'addon CuisineMarchands (PNJ, zone, mapID, position, composants).
A9: Marchands_recettes : recettes de cuisine vendues par des marchands (relevés en jeu), reliées aux recettes et au plan de quêtes.
A10: Rangs_métier : paliers d'apprentissage (Apprenti → Artisan).
A11: Sources_données : provenance et limites des données.
A13: Cellules à remplir
A14: Onglet Sources : les données viennent de Wowhead Classic (1.15.8), PAS de la bêta Forever. À confirmer en jeu : zones et niveaux peuvent différer.
... A32: Licence : QuestieDB (GPL v3, à confirmer) et AtlasLoot Classic (GPL v2) : publier l'addon avec ces données impose une licence compatible GPL, un fichier LICENSE et des crédits.

Sheet Recettes
A1: id_recette | B1: Type d'id | C1: Recette | D1: Nouveau dans Forever | E1: Appris chez un maître | F1: Qté produite | G1: Orange | H1: Jaune | I1: Vert | J1: Gris | K1: Brut (source) | L1: Contrôle | M1: Nb composants | N1: Orange (QuestieDB)
A2: 279981 | B2: sort | C2: Kit de feu de camp basique | D2: Oui | E2: Oui | F2: 1 | H2: 1 | I2: 3 | J2: 5 | K2: 135 | L2: OK | M2: =COUNTIF(Composants!A:A,A2) -> 1
A3: 249871 | B3: objet | C3: Frappé venimeux | D3: Oui | E3: Non | F3: 1 | K3: 2551015 | L3: À vérifier | M3: =COUNTIF(Composants!A:A,A3) -> 3
A4: 263509 | B4: objet | C4: Soufflé de Mur-Céleste | D4: Oui | E4: Non | F4: 1 | K4: 25203345 | L4: À vérifier | M4: =COUNTIF(Composants!A:A,A4) -> 2
A5: 818 | B5: sort | C5: Feu de camp basique | D5: Non | E5: Oui | F5: 1 | H5: 25 | I5: 50 | J5: 75 | K5: 255075 | L5: OK | M5: =COUNTIF(Composants!A:A,A5) -> 1 | N5: 25
A6: 249865 | B6: objet | C6: Thé de sérénité | D6: Oui | E6: Non | F6: 1 | G6: 25 | H6: 25 | I6: 45 | J6: 65 | K6: 25254565 | L6: OK | M6: =COUNTIF(Composants!A:A,A6) -> 2
A7: 263512 | B7: objet | C7: Bouchées à la chair de pinces | D7: Oui | E7: Non | F7: 1 | K7: 35304355 | L7: À vérifier | M7: =COUNTIF(Composants!A:A,A7) -> 2
A8: 250079 | B8: objet | C8: Délicieuses bouchées au raptor | D8: Oui | E8: Non | F8: 1 | G8: 25 | H8: 35 | I8: 55 | J8: 75 | K8: 25355575 | L8: OK | M8: =COUNTIF(Composants!A:A,A8) -> 2
A9: 6888 | B9: objet | C9: Oeufs aux herbes | D9: Non | E9: Oui | F9: 1 | H9: 45 | I9: 65 | J9: 85 | K9: 456585 | L9: OK | M9: =COUNTIF(Composants!A:A,A9) -> 2 | N9: 1
A10: 2679 | B10: objet | C10: Viande de loup grillée | D10: Non | E10: Oui | F10: 1 | H10: 45 | I10: 65 | J10: 85 | K10: 456585 | L10: OK | M10: =COUNTIF(Composants!A:A,A10) -> 1 | N10: 1
A11: 2681 | B11: objet | C11: Viande de sanglier rôtie | D11: Non | E11: Oui | F11: 1 | H11: 45 | I11: 65 | J11: 85 | K11: 456585 | L11: OK | M11: =COUNTIF(Composants!A:A,A11) -> 1 | N11: 1
A12: 12224 | B12: objet | C12: Aile de chauve-souris croustillante | D12: Non | E12: Non | F12: 1 | G12: 1 | H12: 45 | I12: 65 | J12: 85 | K12: 1456585 | L12: OK | M12: =COUNTIF(Composants!A:A,A12) -> 2 | N12: 1
A13: 17197 | B13: objet | C13: Biscuit de pain d'épice | D13: Non | E13: Non | F13: 1 | G13: 1 | H13: 45 | I13: 65 | J13: 85 | K13: 1456585 | L13: OK | M13: =COUNTIF(Composants!A:A,A13) -> 2 | N13: 1
A14: 6290 | B14: objet | C14: Goujon brillant | D14: Non | E14: Non | F14: 1 | G14: 1 | H14: 45 | I14: 65 | J14: 85 | K14: 1456585 | L14: OK | M14: =COUNTIF(Composants!A:A,A14) -> 1 | N14: 1
A15: 787 | B15: objet | C15: Maquereau ombré | D15: Non | E15: Non | F15: 1 | G15: 1 | H15: 45 | I15: 65 | J15: 85 | K15: 1456585 | L15: OK | M15: =COUNTIF(Composants!A:A,A15) -> 1 | N15: 1
A16: 2680 | B16: objet | C16: Viande de loup épicée | D16: Non | E16: Oui | F16: 1 | H16: 50 | I16: 70 | J16: 90 | K16: 507090 | L16: OK | M16: =COUNTIF(Composants!A:A,A16) -> 2 | N16: 30
A17: 5472 | B17: objet | C17: Kébab d'araignée kaldorei | D17: Non | E17: Non | F17: 1 | G17: 10 | H17: 50 | I17: 70 | J17: 90 | K17: 10507090 | L17: OK | M17: =COUNTIF(Composants!A:A,A17) -> 1 | N17: 10
A18: 5473 | B18: objet | C18: Surprise du scorpide | D18: Non | E18: Non | F18: 1 | G18: 20 | H18: 60 | I18: 80 | J18: 100 | K18: 206080100 | L18: OK | M18: =COUNTIF(Composants!A:A,A18) -> 1 | N18: 20
A19: 2888 | B19: objet | C19: Côtes de sanglier à la bière | D19: Non | E19: Non | F19: 1 | G19: 25 | H19: 60 | I19: 80 | J19: 100 | K19: 256080100 | L19: OK | M19: =COUNTIF(Composants!A:A,A19) -> 2 | N19: 25
A20: 17198 | B20: objet | C20: Lait de poule | D20: Non | E20: Non | F20: 1 | G20: 35 | H20: 75 | I20: 95 | J20: 115 | K20: 357595115 | L20: OK | M20: =COUNTIF(Composants!A:A,A20) -> 4 | N20: 35
A21: 5474 | B21: objet | C21: Viande de kodo rôtie | D21: Non | E21: Non | F21: 2 | G21: 35 | H21: 75 | I21: 95 | J21: 115 | K21: 357595115 | L21: OK | M21: =COUNTIF(Composants!A:A,A21) -> 2 | N21: 35
A22: 250080 | B22: objet | C22: Omelette de petit déjeuner | D22: Oui | E22: Non | F22: 1 | G22: 75 | H22: 75 | I22: 93 | J22: 110 | K22: 757593110 | L22: OK | M22: =COUNTIF(Composants!A:A,A22) -> 2
A23: 6890 | B23: objet | C23: Viande d'ours fumée | D23: Non | E23: Non | F23: 1 | G23: 40 | H23: 80 | I23: 100 | J23: 120 | K23: 4080100120 | L23: OK | M23: =COUNTIF(Composants!A:A,A23) -> 1 | N23: 40
A24: 249872 | B24: objet | C24: Frappé gélatineux | D24: Oui | E24: Non | F24: 1 | K24: 100859095 | L24: À vérifier | M24: =COUNTIF(Composants!A:A,A24) -> 3
A25: 249866 | B25: objet | C25: Thé royal | D25: Oui | E25: Non | F25: 1 | K25: 10085105125 | L25: À vérifier | M25: =COUNTIF(Composants!A:A,A25) -> 2
A26: 5525 | B26: objet | C26: Palourdes bouillies | D26: Non | E26: Oui | F26: 1 | H26: 90 | I26: 110 | J26: 130 | K26: 90110130 | L26: OK | M26: =COUNTIF(Composants!A:A,A26) -> 2 | N26: 50
A27: 2684 | B27: objet | C27: Steak de coyote | D27: Non | E27: Oui | F27: 1 | H27: 90 | I27: 110 | J27: 130 | K27: 90110130 | L27: OK | M27: =COUNTIF(Composants!A:A,A27) -> 1 | N27: 65
A28: 5477 | B28: objet | C28: Brouet de trotteur | D28: Non | E28: Non | F28: 2 | G28: 50 | H28: 90 | I28: 110 | J28: 130 | K28: 5090110130 | L28: OK | M28: =COUNTIF(Composants!A:A,A28) -> 2 | N28: 50
A29: 6316 | B29: objet | C29: Délice de furie du loch | D29: Non | E29: Non | F29: 1 | G29: 50 | H29: 90 | I29: 110 | J29: 130 | K29: 5090110130 | L29: OK | M29: =COUNTIF(Composants!A:A,A29) -> 2 | N29: 50
A30: 5476 | B30: objet | C30: Filet de furie | D30: Non | E30: Non | F30: 2 | G30: 50 | H30: 90 | I30: 110 | J30: 130 | K30: 5090110130 | L30: OK | M30: =COUNTIF(Composants!A:A,A30) -> 2 | N30: 50
A31: 4592 | B31: objet | C31: Lutjan à longue mâchoire | D31: Non | E31: Non | F31: 1 | G31: 50 | H31: 90 | I31: 110 | J31: 130 | K31: 5090110130 | L31: OK | M31: =COUNTIF(Composants!A:A,A31) -> 1 | N31: 50
A32: 5095 | B32: objet | C32: Thon arc-en-ciel | D32: Non | E32: Non | F32: 1 | G32: 50 | H32: 90 | I32: 110 | J32: 130 | K32: 5090110130 | L32: OK | M32: =COUNTIF(Composants!A:A,A32) -> 1 | N32: 50
A33: 724 | B33: objet | C33: Tourte au foie de Broche-tripes | D33: Non | E33: Non | F33: 1 | G33: 50 | H33: 90 | I33: 110 | J33: 130 | K33: 5090110130 | L33: OK | M33: =COUNTIF(Composants!A:A,A33) -> 2 | N33: 50
A34: 279961 | B34: objet | C34: Kit de feu de camp de compagnon | D34: Oui | E34: Non | F34: 1 | G34: 90 | H34: 90 | I34: 115 | J34: 140 | K34: 9090115140 | L34: OK | M34: =COUNTIF(Composants!A:A,A34) -> 1
A35: 3220 | B35: objet | C35: Boudin | D35: Non | E35: Non | F35: 2 | G35: 60 | H35: 100 | I35: 120 | J35: 140 | K35: 60100120140 | L35: OK | M35: =COUNTIF(Composants!A:A,A35) -> 3 | N35: 60
A36: 7676 | B36: objet | C36: Thé de chardon | D36: Non | E36: Non | F36: 1 | G36: 60 | H36: 100 | I36: 120 | J36: 140 | K36: 60100120140 | L36: OK | M36: =COUNTIF(Composants!A:A,A36) -> 2 | N36: 60
A37: 2683 | B37: objet | C37: Beignet de crabe | D37: Non | E37: Oui | F37: 1 | H37: 115 | I37: 135 | J37: 155 | K37: 115135155 | L37: OK | M37: =COUNTIF(Composants!A:A,A37) -> 2 | N37: 75
A38: 250077 | B38: objet | C38: Émincé de raptor aux deux épices | D38: Oui | E38: Non | F38: 1 | G38: 75 | H38: 115 | I38: 133 | J38: 150 | K38: 75115133150 | L38: OK | M38: =COUNTIF(Composants!A:A,A38) -> 2
A39: 733 | B39: objet | C39: Ragoût de la marche de l'Ouest | D39: Non | E39: Non | F39: 1 | G39: 75 | H39: 115 | I39: 135 | J39: 155 | K39: 75115135155 | L39: OK | M39: =COUNTIF(Composants!A:A,A39) -> 3 | N39: 75
A40: 2687 | B40: objet | C40: Côtes de porc séchées | D40: Non | E40: Oui | F40: 1 | H40: 120 | I40: 140 | J40: 160 | K40: 120140160 | L40: OK | M40: =COUNTIF(Composants!A:A,A40) -> 2 | N40: 110
...

Sheet Plan_quêtes
A1: Quête n° | B1: Rang requis | C1: Compétence début | D1: Compétence fin | E1: Recette | F1: id_recette | G1: Couleur | H1: Chance par craft | I1: Nb de crafts | J1: Obtention de la recette | K1: Intitulé de quête | L1: Ingrédients sans source | M1: Détail d'obtention (QuestieDB / web)
A2: 1 | B2: =INDEX(Rangs_métier!$A$2:$A$5,MATCH(C2,Rangs_métier!$B$2:$B$5,1)) -> Apprenti | C2: 1 | D2: 45 | E2: Aile de chauve-souris croustillante | F2: 12224 | G2: Orange | H2: =INDEX(Hypothèses!$B$4:$B$6,MATCH(G2,Hypothèses!$A$4:$A$6,0)) -> 1 | I2: =ROUNDUP((D2-C2)/H2,0) -> 44 | J2: =IF(INDEX(Recettes!$E:$E,MATCH(F2,Recettes!$A:$A,0))="Oui","Maître",IFERROR("Marchand : "&INDEX(Marchands_recettes!$B:$B,MATCH(F2,Marchands_recettes!$I:$I,0)),"Autre (vendeur / quête / butin)")) -> Marchand : Abigail Shiel | K2: ="Cuisiner "&I2&"× "&E2&" (compétence "&C2&" → "&D2&")" -> Cuisiner 44× Aile de chauve-souris croustillante (compétence 1 → 45) | L2: =COUNTIFS(Plan_matériaux!$A:$A,A2,Plan_matériaux!$J:$J,"À renseigner") -> 0 | M2: Abigail Shiel (Clairières de Tirisfal, 61 / 52,4) - relevé en jeu.
A3: 2 | B3: =INDEX(Rangs_métier!$A$2:$A$5,MATCH(C3,Rangs_métier!$B$2:$B$5,1)) -> Apprenti | C3: 45 | D3: 80 | E3: Viande d'ours fumée | F3: 6890 | G3: Orange | H3: =INDEX(Hypothèses!$B$4:$B$6,MATCH(G3,Hypothèses!$A$4:$A$6,0)) -> 1 | I3: =ROUNDUP((D3-C3)/H3,0) -> 35 | J3: =IF(INDEX(Recettes!$E:$E,MATCH(F3,Recettes!$A:$A,0))="Oui","Maître",IFERROR("Marchand : "&INDEX(Marchands_recettes!$B:$B,MATCH(F3,Marchands_recettes!$I:$I,0)),"Autre (vendeur / quête / butin)")) -> Marchand : Andrew Hilbert | K3: ="Cuisiner "&I3&"× "&E3&" (compétence "&C3&" → "&D3&")" -> Cuisiner 35× Viande d'ours fumée (compétence 45 → 80) | L3: =COUNTIFS(Plan_matériaux!$A:$A,A3,Plan_matériaux!$J:$J,"À renseigner") -> 0 | M3: Andrew Hilbert (Forêt des Pins argentés, 43,2 / 40,7) - Recette : Viande d'ours fumée, compétence 40 - QuestieDB, à confirmer en jeu.
A4: 3 | B4: =INDEX(Rangs_métier!$A$2:$A$5,MATCH(C4,Rangs_métier!$B$2:$B$5,1)) -> Compagnon | C4: 80 | D4: 120 | E4: Côtes de porc séchées | F4: 2687 | G4: Orange | H4: =INDEX(Hypothèses!$B$4:$B$6,MATCH(G4,Hypothèses!$A$4:$A$6,0)) -> 1 | I4: =ROUNDUP((D4-C4)/H4,0) -> 40 | J4: =IF(INDEX(Recettes!$E:$E,MATCH(F4,Recettes!$A:$A,0))="Oui","Maître",IFERROR("Marchand : "&INDEX(Marchands_recettes!$B:$B,MATCH(F4,Marchands_recettes!$I:$I,0)),"Autre (vendeur / quête / butin)")) -> Maître | K4: ="Cuisiner "&I4&"× "&E4&" (compétence "&C4&" → "&D4&")" -> Cuisiner 40× Côtes de porc séchées (compétence 80 → 120) | L4: =COUNTIFS(Plan_matériaux!$A:$A,A4,Plan_matériaux!$J:$J,"À renseigner") -> 0 | M4: Maître de cuisine, Horde : Zamja (Orgrimmar 57,4 / 54), Eunice Burch (Fossoyeuse 62,1 / 44,9), Aska Mistrunner (Pitons-du-Tonnerre 50,7 / 53,1). Niveau orange : 110 (QuestieDB) contre 80 (hypothèse) - à vérifier en jeu.
A5: 4 | B5: =INDEX(Rangs_métier!$A$2:$A$5,MATCH(C5,Rangs_métier!$B$2:$B$5,1)) -> Compagnon | C5: 120 | D5: 160 | E5: Gombo de crocilisque | F5: 3664 | G5: Orange | H5: =INDEX(Hypothèses!$B$4:$B$6,MATCH(G5,Hypothèses!$A$4:$A$6,0)) -> 1 | I5: =ROUNDUP((D5-C5)/H5,0) -> 40 | J5: =IF(INDEX(Recettes!$E:$E,MATCH(F5,Recettes!$A:$A,0))="Oui","Maître",IFERROR("Marchand : "&INDEX(Marchands_recettes!$B:$B,MATCH(F5,Marchands_recettes!$I:$I,0)),"Autre (vendeur / quête / butin)")) -> Autre (vendeur / quête / butin) | K5: ="Cuisiner "&I5&"× "&E5&" (compétence "&C5&" → "&D5&")" -> Cuisiner 40× Gombo de crocilisque (compétence 120 → 160) | L5: =COUNTIFS(Plan_matériaux!$A:$A,A5,Plan_matériaux!$J:$J,"À renseigner") -> 0 | M5: Aucune source Horde connue dans QuestieDB (vendeur Kendor Kabonka à Hurlevent et quête 471 : Alliance). Piste Horde : Côtelettes de lion épicées (Zargh, Les Tarides 52,6 / 29,8, compétence 125) - à évaluer.
A6: 5 | B6: =INDEX(Rangs_métier!$A$2:$A$5,MATCH(C6,Rangs_métier!$B$2:$B$5,1)) -> Expert | C6: 160 | D6: 190 | E6: Délicieux steak de lion | F6: 3728 | G6: Orange | H6: =INDEX(Hypothèses!$B$4:$B$6,MATCH(G6,Hypothèses!$A$4:$A$6,0)) -> 1 | I6: =ROUNDUP((D6-C6)/H6,0) -> 30 | J6: =IF(INDEX(Recettes!$E:$E,MATCH(F6,Recettes!$A:$A,0))="Oui","Maître",IFERROR("Marchand : "&INDEX(Marchands_recettes!$B:$B,MATCH(F6,Marchands_recettes!$I:$I,0)),"Autre (vendeur / quête / butin)")) -> Autre (vendeur / quête / butin) | K6: ="Cuisiner "&I6&"× "&E6&" (compétence "&C6&" → "&D6&")" -> Cuisiner 30× Délicieux steak de lion (compétence 160 → 190) | L6: =COUNTIFS(Plan_matériaux!$A:$A,A6,Plan_matériaux!$J:$J,"À renseigner") -> 0 | M6: Aucune source Horde connue dans QuestieDB (récompense de la quête 564 « Un problème très coûteux », Alliance). Piste Horde : Côtelettes de lion épicées (Zargh, Les Tarides) - à évaluer.
A7: 6 | B7: =INDEX(Rangs_métier!$A$2:$A$5,MATCH(C7,Rangs_métier!$B$2:$B$5,1)) -> Expert | C7: 190 | D7: 200 | E7: Bonne vieille viande de brochepâle | F7: 274976 | G7: Orange | H7: =INDEX(Hypothèses!$B$4:$B$6,MATCH(G7,Hypothèses!$A$4:$A$6,0)) -> 1 | I7: =ROUNDUP((D7-C7)/H7,0) -> 10 | J7: =IF(INDEX(Recettes!$E:$E,MATCH(F7,Recettes!$A:$A,0))="Oui","Maître",IFERROR("Marchand : "&INDEX(Marchands_recettes!$B:$B,MATCH(F7,Marchands_recettes!$I:$I,0)),"Autre (vendeur / quête / butin)")) -> Autre (vendeur / quête / butin) | K7: ="Cuisiner "&I7&"× "&E7&" (compétence "&C7&" → "&D7&")" -> Cuisiner 10× Bonne vieille viande de brochepâle (compétence 190 → 200) | L7: =COUNTIFS(Plan_matériaux!$A:$A,A7,Plan_matériaux!$J:$J,"À renseigner") -> 0 | M7: Recette propre à Forever : source inconnue.
A8: 7 | B8: =INDEX(Rangs_métier!$A$2:$A$5,MATCH(C8,Rangs_métier!$B$2:$B$5,1)) -> Expert | C8: 200 | D8: 240 | E8: Saucisse d'araignée | F8: 17222 | G8: Orange | H8: =INDEX(Hypothèses!$B$4:$B$6,MATCH(G8,Hypothèses!$A$4:$A$6,0)) -> 1 | I8: =ROUNDUP((D8-C8)/H8,0) -> 40 | J8: =IF(INDEX(Recettes!$E:$E,MATCH(F8,Recettes!$A:$A,0))="Oui","Maître",IFERROR("Marchand : "&INDEX(Marchands_recettes!$B:$B,MATCH(F8,Marchands_recettes!$I:$I,0)),"Autre (vendeur / quête / butin)")) -> Maître | K8: ="Cuisiner "&I8&"× "&E8&" (compétence "&C8&" → "&D8&")" -> Cuisiner 40× Saucisse d'araignée (compétence 200 → 240) | L8: =COUNTIFS(Plan_matériaux!$A:$A,A8,Plan_matériaux!$J:$J,"À renseigner") -> 0 | M8: Maître de cuisine (voir quête 3 pour les maîtres Horde). Niveau orange 200 (QuestieDB).
A9: 8 | B9: =INDEX(Rangs_métier!$A$2:$A$5,MATCH(C9,Rangs_métier!$B$2:$B$5,1)) -> Artisan | C9: 240 | D9: 265 | E9: Barracuda luisant cuit | F9: 13927 | G9: Orange | H9: =INDEX(Hypothèses!$B$4:$B$6,MATCH(G9,Hypothèses!$A$4:$A$6,0)) -> 1 | I9: =ROUNDUP((D9-C9)/H9,0) -> 25 | J9: =IF(INDEX(Recettes!$E:$E,MATCH(F9,Recettes!$A:$A,0))="Oui","Maître",IFERROR("Marchand : "&INDEX(Marchands_recettes!$B:$B,MATCH(F9,Marchands_recettes!$I:$I,0)),"Autre (vendeur / quête / butin)")) -> Marchand : Kelsey Yance | K9: ="Cuisiner "&I9&"× "&E9&" (compétence "&C9&" → "&D9&")" -> Cuisiner 25× Barracuda luisant cuit (compétence 240 → 265) | L9: =COUNTIFS(Plan_matériaux!$A:$A,A9,Plan_matériaux!$J:$J,"À renseigner") -> 0 | M9: Kelsey Yance (Vallée de Strangleronce, 28,2 / 74,3) - Recette : Barracuda luisant cuit, compétence 225 - QuestieDB, à confirmer en jeu.
A10: 9 | B10: =INDEX(Rangs_métier!$A$2:$A$5,MATCH(C10,Rangs_métier!$B$2:$B$5,1)) -> Artisan | C10: 265 | D10: 285 | E10: Barracuda luisant cuit | F10: 13927 | G10: Jaune | H10: =INDEX(Hypothèses!$B$4:$B$6,MATCH(G10,Hypothèses!$A$4:$A$6,0)) -> 0.75 | I10: =ROUNDUP((D10-C10)/H10,0) -> 27 | J10: =IF(INDEX(Recettes!$E:$E,MATCH(F10,Recettes!$A:$A,0))="Oui","Maître",IFERROR("Marchand : "&INDEX(Marchands_recettes!$B:$B,MATCH(F10,Marchands_recettes!$I:$I,0)),"Autre (vendeur / quête / butin)")) -> Marchand : Kelsey Yance | K10: ="Cuisiner "&I10&"× "&E10&" (compétence "&C10&" → "&D10&")" -> Cuisiner 27× Barracuda luisant cuit (compétence 265 → 285) | L10: =COUNTIFS(Plan_matériaux!$A:$A,A10,Plan_matériaux!$J:$J,"À renseigner") -> 0 | M10: Voir quête 8.
A11: 10 | B11: =INDEX(Rangs_métier!$A$2:$A$5,MATCH(C11,Rangs_métier!$B$2:$B$5,1)) -> Artisan | C11: 285 | D11: 300 | E11: Barracuda luisant cuit | F11: 13927 | G11: Vert | H11: =INDEX(Hypothèses!$B$4:$B$6,MATCH(G11,Hypothèses!$A$4:$A$6,0)) -> 0.25 | I11: =ROUNDUP((D11-C11)/H11,0) -> 60 | J11: =IF(INDEX(Recettes!$E:$E,MATCH(F11,Recettes!$A:$A,0))="Oui","Maître",IFERROR("Marchand : "&INDEX(Marchands_recettes!$B:$B,MATCH(F11,Marchands_recettes!$I:$I,0)),"Autre (vendeur / quête / butin)")) -> Marchand : Kelsey Yance | K11: ="Cuisiner "&I11&"× "&E11&" (compétence "&C11&" → "&D11&")" -> Cuisiner 60× Barracuda luisant cuit (compétence 285 → 300) | L11: =COUNTIFS(Plan_matériaux!$A:$A,A11,Plan_matériaux!$J:$J,"À renseigner") -> 0 | M11: Voir quête 8.

Sheet Plan_matériaux
A1: Quête n° | B1: Recette | C1: id_ingrédient | D1: Ingrédient | E1: Qté par craft | F1: Nb de crafts | G1: Total à récolter | H1: Type de source | I1: Zone (1re source) | J1: Statut source
A2: 1 | B2: =INDEX(Plan_quêtes!$E$2:$E$11,A2) -> Aile de chauve-souris croustillante | C2: 12223 | D2: Aile de chauve-souris charnue | E2: =SUMIFS(Composants!$E:$E,Composants!$A:$A,INDEX(Plan_quêtes!$F$2:$F$11,A2),Composants!$C:$C,C2) -> 1 | F2: =INDEX(Plan_quêtes!$I$2:$I$11,A2) -> 44 | G2: =E2*F2 -> 44 | H2: =IFERROR(INDEX(Sources!$C:$C,MATCH(C2,Sources!$A:$A,0)),"—") -> Monstre | I2: =IFERROR(IF(INDEX(Sources!$E:$E,MATCH(C2,Sources!$A:$A,0))="","",INDEX(Sources!$E:$E,MATCH(C2,Sources!$A:$A,0))),"—") -> Tirisfal Glades | J2: =INDEX(Ingrédients!$F$2:$F$98,MATCH(C2,Ingrédients!$A$2:$A$98,0)) -> Renseigné
A3: 1 | B3: =INDEX(Plan_quêtes!$E$2:$E$11,A3) -> Aile de chauve-souris croustillante | C3: 2678 | D3: Epices douces | E3: =SUMIFS(Composants!$E:$E,Composants!$A:$A,INDEX(Plan_quêtes!$F$2:$F$11,A3),Composants!$C:$C,C3) -> 1 | F3: =INDEX(Plan_quêtes!$I$2:$I$11,A3) -> 44 | G3: =E3*F3 -> 44 | H3: =IFERROR(INDEX(Sources!$C:$C,MATCH(C3,Sources!$A:$A,0)),"—") -> Vendeur | I3: =IFERROR(IF(INDEX(Sources!$E:$E,MATCH(C3,Sources!$A:$A,0))="","",INDEX(Sources!$E:$E,MATCH(C3,Sources!$A:$A,0))),"—") -> Tirisfal Glades | J3: =INDEX(Ingrédients!$F$2:$F$98,MATCH(C3,Ingrédients!$A$2:$A$98,0)) -> Renseigné
A4: 2 | B4: =INDEX(Plan_quêtes!$E$2:$E$11,A4) -> Viande d'ours fumée | C4: 3173 | D4: Viande d'ours | E4: =SUMIFS(Composants!$E:$E,Composants!$A:$A,INDEX(Plan_quêtes!$F$2:$F$11,A4),Composants!$C:$C,C4) -> 1 | F4: =INDEX(Plan_quêtes!$I$2:$I$11,A4) -> 35 | G4: =E4*F4 -> 35 | H4: =IFERROR(INDEX(Sources!$C:$C,MATCH(C4,Sources!$A:$A,0)),"—") -> Monstre | I4: =IFERROR(IF(INDEX(Sources!$E:$E,MATCH(C4,Sources!$A:$A,0))="","",INDEX(Sources!$E:$E,MATCH(C4,Sources!$A:$A,0))),"—") -> Darkshore | J4: =INDEX(Ingrédients!$F$2:$F$98,MATCH(C4,Ingrédients!$A$2:$A$98,0)) -> Renseigné
A5: 3 | B5: =INDEX(Plan_quêtes!$E$2:$E$11,A5) -> Côtes de porc séchées | C5: 2677 | D5: Côtes de sanglier | E5: =SUMIFS(Composants!$E:$E,Composants!$A:$A,INDEX(Plan_quêtes!$F$2:$F$11,A5),Composants!$C:$C,C5) -> 1 | F5: =INDEX(Plan_quêtes!$I$2:$I$11,A5) -> 40 | G5: =E5*F5 -> 40 | H5: =IFERROR(INDEX(Sources!$C:$C,MATCH(C5,Sources!$A:$A,0)),"—") -> Monstre | I5: =IFERROR(IF(INDEX(Sources!$E:$E,MATCH(C5,Sources!$A:$A,0))="","",INDEX(Sources!$E:$E,MATCH(C5,Sources!$A:$A,0))),"—") -> Loch Modan | J5: =INDEX(Ingrédients!$F$2:$F$98,MATCH(C5,Ingrédients!$A$2:$A$98,0)) -> Renseigné
A6: 3 | B6: =INDEX(Plan_quêtes!$E$2:$E$11,A6) -> Côtes de porc séchées | C6: 2678 | D6: Epices douces | E6: =SUMIFS(Composants!$E:$E,Composants!$A:$A,INDEX(Plan_quêtes!$F$2:$F$11,A6),Composants!$C:$C,C6) -> 1 | F6: =INDEX(Plan_quêtes!$I$2:$I$11,A6) -> 40 | G6: =E6*F6 -> 40 | H6: =IFERROR(INDEX(Sources!$C:$C,MATCH(C6,Sources!$A:$A,0)),"—") -> Vendeur | I6: =IFERROR(IF(INDEX(Sources!$E:$E,MATCH(C6,Sources!$A:$A,0))="","",INDEX(Sources!$E:$E,MATCH(C6,Sources!$A:$A,0))),"—") -> Tirisfal Glades | J6: =INDEX(Ingrédients!$F$2:$F$98,MATCH(C6,Ingrédients!$A$2:$A$98,0)) -> Renseigné
A7: 4 | B7: =INDEX(Plan_quêtes!$E$2:$E$11,A7) -> Gombo de crocilisque | C7: 3667 | D7: Viande de crocilisque tendre | E7: =SUMIFS(Composants!$E:$E,Composants!$A:$A,INDEX(Plan_quêtes!$F$2:$F$11,A7),Composants!$C:$C,C7) -> 1 | F7: =INDEX(Plan_quêtes!$I$2:$I$11,A7) -> 40 | G7: =E7*F7 -> 40 | H7: =IFERROR(INDEX(Sources!$C:$C,MATCH(C7,Sources!$A:$A,0)),"—") -> Monstre | I7: =IFERROR(IF(INDEX(Sources!$E:$E,MATCH(C7,Sources!$A:$A,0))="","",INDEX(Sources!$E:$E,MATCH(C7,Sources!$A:$A,0))),"—") -> Wetlands | J7: =INDEX(Ingrédients!$F$2:$F$98,MATCH(C7,Ingrédients!$A$2:$A$98,0)) -> Renseigné
A8: 4 | B8: =INDEX(Plan_quêtes!$E$2:$E$11,A8) -> Gombo de crocilisque | C8: 2692 | D8: Epices fortes | E8: =SUMIFS(Composants!$E:$E,Composants!$A:$A,INDEX(Plan_quêtes!$F$2:$F$11,A8),Composants!$C:$C,C8) -> 1 | F8: =INDEX(Plan_quêtes!$I$2:$I$11,A8) -> 40 | G8: =E8*F8 -> 40 | H8: =IFERROR(INDEX(Sources!$C:$C,MATCH(C8,Sources!$A:$A,0)),"—") -> Vendeur | I8: =IFERROR(IF(INDEX(Sources!$E:$E,MATCH(C8,Sources!$A:$A,0))="","",INDEX(Sources!$E:$E,MATCH(C8,Sources!$A:$A,0))),"—") -> Undercity | J8: =INDEX(Ingrédients!$F$2:$F$98,MATCH(C8,Ingrédients!$A$2:$A$98,0)) -> Renseigné
A9: 5 | B9: =INDEX(Plan_quêtes!$E$2:$E$11,A9) -> Délicieux steak de lion | C9: 3731 | D9: Viande de lion | E9: =SUMIFS(Composants!$E:$E,Composants!$A:$A,INDEX(Plan_quêtes!$F$2:$F$11,A9),Composants!$C:$C,C9) -> 2 | F9: =INDEX(Plan_quêtes!$I$2:$I$11,A9) -> 30 | G9: =E9*F9 -> 60 | H9: =IFERROR(INDEX(Sources!$C:$C,MATCH(C9,Sources!$A:$A,0)),"—") -> Monstre | I9: =IFERROR(IF(INDEX(Sources!$E:$E,MATCH(C9,Sources!$A:$A,0))="","",INDEX(Sources!$E:$E,MATCH(C9,Sources!$A:$A,0))),"—") -> Hillsbrad Foothills | J9: =INDEX(Ingrédients!$F$2:$F$98,MATCH(C9,Ingrédients!$A$2:$A$98,0)) -> Renseigné
A10: 5 | B10: =INDEX(Plan_quêtes!$E$2:$E$11,A10) -> Délicieux steak de lion | C10: 3713 | D10: Epices apaisantes | E10: =SUMIFS(Composants!$E:$E,Composants!$A:$A,INDEX(Plan_quêtes!$F$2:$F$11,A10),Composants!$C:$C,C10) -> 1 | F10: =INDEX(Plan_quêtes!$I$2:$I$11,A10) -> 30 | G10: =E10*F10 -> 30 | H10: =IFERROR(INDEX(Sources!$C:$C,MATCH(C10,Sources!$A:$A,0)),"—") -> Vendeur | I10: =IFERROR(IF(INDEX(Sources!$E:$E,MATCH(C10,Sources!$A:$A,0))="","",INDEX(Sources!$E:$E,MATCH(C10,Sources!$A:$A,0))),"—") -> Undercity | J10: =INDEX(Ingrédients!$F$2:$F$98,MATCH(C10,Ingrédients!$A$2:$A$98,0)) -> Renseigné
A11: 6 | B11: =INDEX(Plan_quêtes!$E$2:$E$11,A11) -> Bonne vieille viande de brochepâle | C11: 769 | D11: Morceau de viande de sanglier | E11: =SUMIFS(Composants!$E:$E,Composants!$A:$A,INDEX(Plan_quêtes!$F$2:$F$11,A11),Composants!$C:$C,C11) -> 2 | F11: =INDEX(Plan_quêtes!$I$2:$I$11,A11) -> 10 | G11: =E11*F11 -> 20 | H11: =IFERROR(INDEX(Sources!$C:$C,MATCH(C11,Sources!$A:$A,0)),"—") -> Monstre | I11: =IFERROR(IF(INDEX(Sources!$E:$E,MATCH(C11,Sources!$A:$A,0))="","",INDEX(Sources!$E:$E,MATCH(C11,Sources!$A:$A,0))),"—") -> Elwynn Forest | J11: =INDEX(Ingrédients!$F$2:$F$98,MATCH(C11,Ingrédients!$A$2:$A$98,0)) -> Renseigné
A12: 6 | B12: =INDEX(Plan_quêtes!$E$2:$E$11,A12) -> Bonne vieille viande de brochepâle | C12: 2678 | D12: Epices douces | E12: =SUMIFS(Composants!$E:$E,Composants!$A:$A,INDEX(Plan_quêtes!$F$2:$F$11,A12),Composants!$C:$C,C12) -> 1 | F12: =INDEX(Plan_quêtes!$I$2:$I$11,A12) -> 10 | G12: =E12*F12 -> 10 | H12: =IFERROR(INDEX(Sources!$C:$C,MATCH(C12,Sources!$A:$A,0)),"—") -> Vendeur | I12: =IFERROR(IF(INDEX(Sources!$E:$E,MATCH(C12,Sources!$A:$A,0))="","",INDEX(Sources!$E:$E,MATCH(C12,Sources!$A:$A,0))),"—") -> Tirisfal Glades | J12: =INDEX(Ingrédients!$F$2:$F$98,MATCH(C12,Ingrédients!$A$2:$A$98,0)) -> Renseigné
A13: 7 | B13: =INDEX(Plan_quêtes!$E$2:$E$11,A13) -> Saucisse d'araignée | C13: 12205 | D13: Viande d'araignée blanche | E13: =SUMIFS(Composants!$E:$E,Composants!$A:$A,INDEX(Plan_quêtes!$F$2:$F$11,A13),Composants!$C:$C,C13) -> 2 | F13: =INDEX(Plan_quêtes!$I$2:$I$11,A13) -> 40 | G13: =E13*F13 -> 80 | H13: =IFERROR(INDEX(Sources!$C:$C,MATCH(C13,Sources!$A:$A,0)),"—") -> Monstre | I13: =IFERROR(IF(INDEX(Sources!$E:$E,MATCH(C13,Sources!$A:$A,0))="","",INDEX(Sources!$E:$E,MATCH(C13,Sources!$A:$A,0))),"—") -> Dustwallow Marsh | J13: =INDEX(Ingrédients!$F$2:$F$98,MATCH(C13,Ingrédients!$A$2:$A$98,0)) -> Renseigné
... A19: 10 | B19: =INDEX(Plan_quêtes!$E$2:$E$11,A19) -> Barracuda luisant cuit | C19: 3713 | D19: Epices apaisantes | E19: =SUMIFS(Composants!$E:$E,Composants!$A:$A,INDEX(Plan_quêtes!$F$2:$F$11,A19),Composants!$C:$C,C19) -> 1 | F19: =INDEX(Plan_quêtes!$I$2:$I$11,A19) -> 60 | G19: =E19*F19 -> 60 | H19: =IFERROR(INDEX(Sources!$C:$C,MATCH(C19,Sources!$A:$A,0)),"—") -> Vendeur | I19: =IFERROR(IF(INDEX(Sources!$E:$E,MATCH(C19,Sources!$A:$A,0))="","",INDEX(Sources!$E:$E,MATCH(C19,Sources!$A:$A,0))),"—") -> Undercity | J19: =INDEX(Ingrédients!$F$2:$F$98,MATCH(C19,Ingrédients!$A$2:$A$98,0)) -> Renseigné

Sheet Hypothèses
A1: Hypothèses du plan de progression
A3: Couleur de la recette | B3: Chance de gain de compétence par craft
A4: Orange | B4: 1
A5: Jaune | B5: 0.75
A6: Vert | B6: 0.25
A9: Les chances (100 % / 75 % / 25 %) sont des valeurs de référence de WoW Classic, pas des valeurs confirmées pour Forever : modifiables dans les cellules jaunes.
A10: La source dit seulement : orange = toujours, jaune = souvent, vert = rarement, gris = jamais.
A11: Règle du plan : à chaque point de compétence, choisir la recette de meilleure couleur (orange > jaune > vert) ; à couleur égale, privilégier celle dont tous les ingrédients ont une source renseignée, puis la plus récemment débloquée (progression naturelle, ingrédients de niveau adapté), puis celle qui reste utile le plus longtemps.
A12: Recettes apprises chez un maître : la source ne donne pas le niveau orange. Hypothèse : orange = jaune − 40 (écart observé sur plusieurs recettes Classic, à confirmer en jeu).
A13: Cible du plan : compétence 300. Les kits de feu de camp sont exclus. Les 12 recettes « À vérifier » sont exclues.
A14: Non pris en compte : prix, coût des recettes vendues, niveau du personnage requis, disponibilité réelle des recettes de vendeur ou de quête.
A15: Nombre de crafts = arrondi supérieur de (compétence fin − début) / chance.

Sheet Composants
A1: id_recette | B1: Recette | C1: id_ingrédient | D1: Ingrédient | E1: Quantité
A2: 279981 | B2: Kit de feu de camp basique | C2: 4470 | D2: Bois simple | E2: 1
A3: 249871 | B3: Frappé venimeux | C3: 159 | D3: Eau de source | E3: 1
A4: 249871 | B4: Frappé venimeux | C4: 2678 | D4: Epices douces | E4: 1
A5: 249871 | B5: Frappé venimeux | C5: 1475 | D5: Petite glande à venin | E5: 1
A6: 263509 | B6: Soufflé de Mur-Céleste | C6: 6889 | D6: Petit oeuf | E6: 2
A7: 263509 | B7: Soufflé de Mur-Céleste | C7: 10284 | D7: Farine simple | E7: 1
A8: 818 | B8: Feu de camp basique | C8: 4470 | D8: Bois simple | E8: 1
A9: 249865 | B9: Thé de sérénité | C9: 159 | D9: Eau de source | E9: 1
A10: 249865 | B10: Thé de sérénité | C10: 2447 | D10: Pacifique | E10: 2
A11: 263512 | B11: Bouchées à la chair de pinces | C11: 2675 | D11: Pince de clampant | E11: 1
A12: 263512 | B12: Bouchées à la chair de pinces | C12: 10284 | D12: Farine simple | E12: 1
A13: 250079 | B13: Délicieuses bouchées au raptor | C13: 3685 | D13: Oeuf de raptor | E13: 1
... A240: 21023 | B240: Pyro-côtelettes de chimaerok à la Dirge | C240: 21024 | D240: Filet de chimaerok | E240: 1

Sheet Ingrédients
A1: id_ingrédient | B1: Ingrédient | C1: Nb recettes qui l'utilisent | D1: Quantité totale (toutes recettes) | E1: Nb sources renseignées | F1: Statut | G1: Besoin total (plan, compétence 300)
A2: 3404 | B2: Aile de busard | C2: =COUNTIF(Composants!C:C,A2) -> 1 | D2: =SUMIF(Composants!C:C,A2,Composants!E:E) -> 1 | E2: =COUNTIF(Sources!A:A,A2) -> 4 | F2: =IF(E2>0,"Renseigné","À renseigner") -> Renseigné | G2: =SUMIF(Plan_matériaux!$C$2:$C$19,A2,Plan_matériaux!$G$2:$G$19) -> 0
A3: 12223 | B3: Aile de chauve-souris charnue | C3: =COUNTIF(Composants!C:C,A3) -> 1 | D3: =SUMIF(Composants!C:C,A3,Composants!E:E) -> 1 | E3: =COUNTIF(Sources!A:A,A3) -> 1 | F3: =IF(E3>0,"Renseigné","À renseigner") -> Renseigné | G3: =SUMIF(Plan_matériaux!$C$2:$C$19,A3,Plan_matériaux!$G$2:$G$19) -> 44
A4: 1468 | B4: Aileron de murloc | C4: =COUNTIF(Composants!C:C,A4) -> 2 | D4: =SUMIF(Composants!C:C,A4,Composants!E:E) -> 3 | E4: =COUNTIF(Sources!A:A,A4) -> 2 | F4: =IF(E4>0,"Renseigné","À renseigner") -> Renseigné | G4: =SUMIF(Plan_matériaux!$C$2:$C$19,A4,Plan_matériaux!$G$2:$G$19) -> 0
A5: 13754 | B5: Barracuda luisant cru | C5: =COUNTIF(Composants!C:C,A5) -> 1 | D5: =SUMIF(Composants!C:C,A5,Composants!E:E) -> 1 | E5: =COUNTIF(Sources!A:A,A5) -> 5 | F5: =IF(E5>0,"Renseigné","À renseigner") -> Renseigné | G5: =SUMIF(Plan_matériaux!$C$2:$C$19,A5,Plan_matériaux!$G$2:$G$19) -> 112
A6: 2894 | B6: Bière au malt Rhapsody | C6: =COUNTIF(Composants!C:C,A6) -> 1 | D6: =SUMIF(Composants!C:C,A6,Composants!E:E) -> 1 | E6: =COUNTIF(Sources!A:A,A6) -> 0 | F6: =IF(E6>0,"Renseigné","À renseigner") -> À renseigner | G6: =SUMIF(Plan_matériaux!$C$2:$C$19,A6,Plan_matériaux!$G$2:$G$19) -> 0
A7: 11291 | B7: Bois d'étoile | C7: =COUNTIF(Composants!C:C,A7) -> 1 | D7: =SUMIF(Composants!C:C,A7,Composants!E:E) -> 1 | E7: =COUNTIF(Sources!A:A,A7) -> 1 | F7: =IF(E7>0,"Renseigné","À renseigner") -> Renseigné | G7: =SUMIF(Plan_matériaux!$C$2:$C$19,A7,Plan_matériaux!$G$2:$G$19) -> 0
A8: 4470 | B8: Bois simple | C8: =COUNTIF(Composants!C:C,A8) -> 2 | D8: =SUMIF(Composants!C:C,A8,Composants!E:E) -> 2 | E8: =COUNTIF(Sources!A:A,A8) -> 2 | F8: =IF(E8>0,"Renseigné","À renseigner") -> Renseigné | G8: =SUMIF(Plan_matériaux!$C$2:$C$19,A8,Plan_matériaux!$G$2:$G$19) -> 0
A9: 272941 | B9: Bûches épaisses | C9: =COUNTIF(Composants!C:C,A9) -> 1 | D9: =SUMIF(Composants!C:C,A9,Composants!E:E) -> 1 | E9: =COUNTIF(Sources!A:A,A9) -> 0 | F9: =IF(E9>0,"Renseigné","À renseigner") -> À renseigner | G9: =SUMIF(Plan_matériaux!$C$2:$C$19,A9,Plan_matériaux!$G$2:$G$19) -> 0
A10: 1081 | B10: Chair croustillante d'araignée | C10: =COUNTIF(Composants!C:C,A10) -> 1 | D10: =SUMIF(Composants!C:C,A10,Composants!E:E) -> 1 | E10: =COUNTIF(Sources!A:A,A10) -> 1 | F10: =IF(E10>0,"Renseigné","À renseigner") -> Renseigné | G10: =SUMIF(Plan_matériaux!$C$2:$C$19,A10,Plan_matériaux!$G$2:$G$19) -> 0
A11: 2674 | B11: Chair de clampant | C11: =COUNTIF(Composants!C:C,A11) -> 1 | D11: =SUMIF(Composants!C:C,A11,Composants!E:E) -> 1 | E11: =COUNTIF(Sources!A:A,A11) -> 3 | F11: =IF(E11>0,"Renseigné","À renseigner") -> Renseigné | G11: =SUMIF(Plan_matériaux!$C$2:$C$19,A11,Plan_matériaux!$G$2:$G$19) -> 0
A12: 5503 | B12: Chair de palourde | C12: =COUNTIF(Composants!C:C,A12) -> 2 | D12: =SUMIF(Composants!C:C,A12,Composants!E:E) -> 2 | E12: =COUNTIF(Sources!A:A,A12) -> 3 | F12: =IF(E12>0,"Renseigné","À renseigner") -> Renseigné | G12: =SUMIF(Plan_matériaux!$C$2:$C$19,A12,Plan_matériaux!$G$2:$G$19) -> 0
A13: 4655 | B13: Chair de palourde géante | C13: =COUNTIF(Composants!C:C,A13) -> 1 | D13: =SUMIF(Composants!C:C,A13,Composants!E:E) -> 1 | E13: =COUNTIF(Sources!A:A,A13) -> 1 | F13: =IF(E13>0,"Renseigné","À renseigner") -> Renseigné | G13: =SUMIF(Plan_matériaux!$C$2:$C$19,A13,Plan_matériaux!$G$2:$G$19) -> 0
... A110: 21024 | B110: Filet de chimaerok | C110: =COUNTIF(Composants!C:C,A110) -> 1 | D110: =SUMIF(Composants!C:C,A110,Composants!E:E) -> 1 | E110: =COUNTIF(Sources!A:A,A110) -> 1 | F110: =IF(E110>0,"Renseigné","À renseigner") -> Renseigné | G110: =SUMIF(Plan_matériaux!$C$2:$C$19,A110,Plan_matériaux!$G$2:$G$19) -> 0

Sheet Sources
A1: id_ingrédient | B1: Ingrédient | C1: Type de source | D1: Source (monstre / objet / pêche / PNJ) | E1: Zone (nom anglais) | F1: Niveau mob (min) | G1: Niveau mob (max) | H1: Taux de butin / de prise (%) | I1: Référence | J1: Notes
A2: 3173 | B2: Viande d'ours | C2: Monstre | D2: Bears | E2: Darkshore | F2: 11 | G2: 17 | I2: Wowhead Classic — Best Cooking Ingredient Farming Spots (1.15.8) | J2: Pas les faux ours (druides) du sud de Silverpine
A3: 3173 | B3: Viande d'ours | C3: Monstre | D3: Bears | E3: Loch Modan | F3: 11 | G3: 17 | I3: Wowhead Classic — Best Cooking Ingredient Farming Spots (1.15.8) | J3: Pas les faux ours (druides) du sud de Silverpine
A4: 3173 | B4: Viande d'ours | C4: Monstre | D4: Bears | E4: Silverpine Forest | F4: 11 | G4: 17 | I4: Wowhead Classic — Best Cooking Ingredient Farming Spots (1.15.8) | J4: Pas les faux ours (druides) du sud de Silverpine
A5: 3730 | B5: Viande de grand ours | C5: Monstre | D5: Bears (Evil Grizzly à Hillsbrad) | E5: Ashenvale | F5: 21 | G5: 30 | I5: Wowhead Classic — Best Cooking Ingredient Farming Spots (1.15.8)
A6: 3730 | B6: Viande de grand ours | C6: Monstre | D6: Bears (Evil Grizzly à Hillsbrad) | E6: Hillsbrad Foothills | F6: 21 | G6: 30 | I6: Wowhead Classic — Best Cooking Ingredient Farming Spots (1.15.8)
A7: 3172 | B7: Tripes de sanglier | C7: Monstre | D7: Mountain Boar, Rugged Boar, Elder Mountain Boar | E7: Loch Modan | I7: Wowhead Classic — Best Cooking Ingredient Farming Spots (1.15.8)
A8: 2677 | B8: Côtes de sanglier | C8: Monstre | D8: Boars (Mountain Boar à Loch Modan ; Goretusk à Westfall) | E8: Loch Modan | F8: 10 | G8: 17 | I8: Wowhead Classic — Best Cooking Ingredient Farming Spots (1.15.8)
A9: 2677 | B9: Côtes de sanglier | C9: Monstre | D9: Boars (Mountain Boar à Loch Modan ; Goretusk à Westfall) | E9: Westfall | F9: 10 | G9: 17 | I9: Wowhead Classic — Best Cooking Ingredient Farming Spots (1.15.8)
A10: 3404 | B10: Aile de busard | C10: Monstre | D10: Carrion Birds (vautours) | E10: Arathi Highlands | F10: 31 | G10: 49 | I10: Wowhead Classic — Best Cooking Ingredient Farming Spots (1.15.8) | J10: Tanaris : rocs plus dispersés
A11: 3404 | B11: Aile de busard | C11: Monstre | D11: Carrion Birds (vautours) | E11: Desolace | F11: 31 | G11: 49 | I11: Wowhead Classic — Best Cooking Ingredient Farming Spots (1.15.8) | J11: Tanaris : rocs plus dispersés
A12: 3404 | B12: Aile de busard | C12: Monstre | D12: Carrion Birds (vautours) | E12: Badlands | F12: 31 | G12: 49 | I12: Wowhead Classic — Best Cooking Ingredient Farming Spots (1.15.8) | J12: Tanaris : rocs plus dispersés
A13: 3404 | B13: Aile de busard | C13: Monstre | D13: Carrion Birds (vautours) | E13: Tanaris | F13: 31 | G13: 49 | I13: Wowhead Classic — Best Cooking Ingredient Farming Spots (1.15.8) | J13: Tanaris : rocs plus dispersés
A14: 769 | B14: Morceau de viande de sanglier | C14: Monstre | D14: Boars | E14: Elwynn Forest | F14: 5 | G14: 17 | I14: Wowhead Classic — Best Cooking Ingredient Farming Spots (1.15.8)
A15: 769 | B15: Morceau de viande de sanglier | C15: Monstre | D15: Boars | E15: Loch Modan | F15: 5 | G15: 17 | I15: Wowhead Classic — Best Cooking Ingredient Farming Spots (1.15.8)
A16: 769 | B16: Morceau de viande de sanglier | C16: Monstre | D16: Boars | E16: Durotar | F16: 5 | G16: 17 | I16: Wowhead Classic — Best Cooking Ingredient Farming Spots (1.15.8)
A17: 5503 | B17: Chair de palourde | C17: Monstre | D17: Threshers, Crawlers, Murlocs, Naga (butin : petit coquillage) | E17: Darkshore | F17: 5 | G17: 22 | I17: Wowhead Classic — Best Cooking Ingredient Farming Spots (1.15.8) | J17: Aussi dans des coquilles géantes immergées (Barrens, Westfall, Ashenvale, Darkshore)
A18: 5503 | B18: Chair de palourde | C18: Monstre | D18: Threshers, Crawlers, Murlocs, Naga (butin : petit coquillage) | E18: Westfall | F18: 5 | G18: 22 | I18: Wowhead Classic — Best Cooking Ingredient Farming Spots (1.15.8) | J18: Aussi dans des coquilles géantes immergées (Barrens, Westfall, Ashenvale, Darkshore)
A19: 5503 | B19: Chair de palourde | C19: Monstre | D19: Threshers, Crawlers, Murlocs, Naga (butin : petit coquillage) | E19: Ashenvale | F19: 5 | G19: 22 | I19: Wowhead Classic — Best Cooking Ingredient Farming Spots (1.15.8) | J19: Aussi dans des coquilles géantes immergées (Barrens, Westfall, Ashenvale, Darkshore)
A20: 2673 | B20: Viande de coyote | C20: Monstre | D20: Coyote, Coyote Packleader | E20: Westfall | F20: 10 | G20: 12 | I20: Wowhead Classic — Best Cooking Ingredient Farming Spots (1.15.8)
A21: 2886 | B21: Côtes de sanglier des rochers | C21: Monstre | D21: Crag Boars | E21: Dun Morogh | F21: 6 | G21: 10 | I21: Wowhead Classic — Best Cooking Ingredient Farming Spots (1.15.8)
A22: 2675 | B22: Pince de clampant | C22: Monstre | D22: Crawlers | E22: Darkshore | F22: 10 | G22: 20 | I22: Wowhead Classic — Best Cooking Ingredient Farming Spots (1.15.8) | J22: Ashenvale : côte de Zoram Strand
A23: 2675 | B23: Pince de clampant | C23: Monstre | D23: Crawlers | E23: Westfall | F23: 10 | G23: 20 | I23: Wowhead Classic — Best Cooking Ingredient Farming Spots (1.15.8) | J23: Ashenvale : côte de Zoram Strand
A24: 2675 | B24: Pince de clampant | C24: Monstre | D24: Crawlers | E24: Ashenvale | F24: 10 | G24: 20 | I24: Wowhead Classic — Best Cooking Ingredient Farming Spots (1.15.8) | J24: Ashenvale : côte de Zoram Strand
A25: 2674 | B25: Chair de clampant | C25: Monstre | D25: Crawlers | E25: Darkshore | F25: 10 | G25: 20 | I25: Wowhead Classic — Best Cooking Ingredient Farming Spots (1.15.8) | J25: Ashenvale : côte de Zoram Strand
A26: 2674 | B26: Chair de clampant | C26: Monstre | D26: Crawlers | E26: Westfall | F26: 10 | G26: 20 | I26: Wowhead Classic — Best Cooking Ingredient Farming Spots (1.15.8) | J26: Ashenvale : côte de Zoram Strand
A27: 2674 | B27: Chair de clampant | C27: Monstre | D27: Crawlers | E27: Ashenvale | F27: 10 | G27: 20 | I27: Wowhead Classic — Best Cooking Ingredient Farming Spots (1.15.8) | J27: Ashenvale : côte de Zoram Strand
A28: 1081 | B28: Chair croustillante d'araignée | C28: Monstre | D28: Murloc Scavenger, Giant Tarantula | E28: Redridge Mountains | F28: 15 | G28: 20 | I28: Wowhead Classic — Best Cooking Ingredient Farming Spots (1.15.8)
A29: 2924 | B29: Viande de crocilisque | C29: Monstre | D29: Loch Crocolisk | E29: Loch Modan | F29: 14 | G29: 15 | I29: Wowhead Classic — Best Cooking Ingredient Farming Spots (1.15.8)
A30: 5051 | B30: Rat fouisseur | C30: Monstre | D30: Dig Rat (entouré de nains de niveau 21-25) | E30: The Barrens | F30: 21 | G30: 25 | I30: Wowhead Classic — Best Cooking Ingredient Farming Spots (1.15.8) | J30: Les rats sont niveau 1 ; niveau 21-25 = les nains autour de Bael Modan
A31: 4655 | B31: Chair de palourde géante | C31: Objet du monde | D31: Giant Clam (coquille géante immergée, à l'ouest de Grom'gol) | E31: Stranglethorn Vale | F31: 35 | G31: 37 | I31: Wowhead Classic — Best Cooking Ingredient Farming Spots (1.15.8) | J31: Murlocs Saltscale élites 35-37 à proximité
A32: 12207 | B32: Oeuf géant | C32: Monstre | D32: Carrion Birds, Owls, Owlbeasts | E32: Tanaris | F32: 41 | G32: 49 | I32: Wowhead Classic — Best Cooking Ingredient Farming Spots (1.15.8)
A33: 12207 | B33: Oeuf géant | C33: Monstre | D33: Carrion Birds, Owls, Owlbeasts | E33: Winterspring | F33: 50 | G33: 59 | I33: Wowhead Classic — Best Cooking Ingredient Farming Spots (1.15.8)
A34: 2251 | B34: Patte d'araignée fondante | C34: Monstre | D34: Spiders (Green Recluse en majorité) | E34: Duskwood | F34: 18 | G34: 36 | I34: Wowhead Classic — Best Cooking Ingredient Farming Spots (1.15.8)
A35: 723 | B35: Foie de Broche-tripes | C35: Monstre | D35: Goretusks | E35: Redridge Mountains | F35: 12 | G35: 17 | I35: Wowhead Classic — Best Cooking Ingredient Farming Spots (1.15.8) | J35: Foie : Redridge et Westfall
A36: 723 | B36: Foie de Broche-tripes | C36: Monstre | D36: Goretusks | E36: Westfall | F36: 12 | G36: 17 | I36: Wowhead Classic — Best Cooking Ingredient Farming Spots (1.15.8) | J36: Foie : Redridge et Westfall
A37: 731 | B37: Groin de Broche-tripes | C37: Monstre | D37: Goretusks (Westfall uniquement) | E37: Westfall | F37: 12 | G37: 17 | I37: Wowhead Classic — Best Cooking Ingredient Farming Spots (1.15.8) | J37: Groin : Westfall uniquement
A38: 12204 | B38: Viande de kodo épaisse | C38: Monstre | D38: Aged Kodo, Dying Kodo, Ancient Kodo | E38: Desolace | F38: 34 | G38: 37 | I38: Wowhead Classic — Best Cooking Ingredient Farming Spots (1.15.8) | J38: Concentration au cimetière des kodos
A39: 5467 | B39: Viande de kodo | C39: Monstre | D39: Kodos | E39: Mulgore | F39: 7 | G39: 26 | I39: Wowhead Classic — Best Cooking Ingredient Farming Spots (1.15.8)
A40: 5467 | B40: Viande de kodo | C40: Monstre | D40: Kodos | E40: The Barrens | F40: 7 | G40: 26 | I40: Wowhead Classic — Best Cooking Ingredient Farming Spots (1.15.8)
...

Sheet Marchands
A1: id_PNJ | B1: Marchand | C1: Zone (client FR) | D1: mapID | E1: X (%) | F1: Y (%) | G1: id_ingrédient | H1: Ingrédient
A2: 2134 | B2: Mme Winters | C2: Clairières de Tirisfal | D2: 1420 | E2: 61.1 | F2: 52.7 | G2: 159 | H2: =IFERROR(INDEX(Ingrédients!$B:$B,MATCH(G2,Ingrédients!$A:$A,0)),"—") -> Eau de source
A3: 2134 | B3: Mme Winters | C3: Clairières de Tirisfal | D3: 1420 | E3: 61.1 | F3: 52.7 | G3: 4470 | H3: =IFERROR(INDEX(Ingrédients!$B:$B,MATCH(G3,Ingrédients!$A:$A,0)),"—") -> Bois simple
A4: 2118 | B4: Abigail Shiel | C4: Clairières de Tirisfal | D4: 1420 | E4: 61 | F4: 52.4 | G4: 2678 | H4: =IFERROR(INDEX(Ingrédients!$B:$B,MATCH(G4,Ingrédients!$A:$A,0)),"—") -> Epices douces
A5: 2118 | B5: Abigail Shiel | C5: Clairières de Tirisfal | D5: 1420 | E5: 61 | F5: 52.4 | G5: 4536 | H5: =IFERROR(INDEX(Ingrédients!$B:$B,MATCH(G5,Ingrédients!$A:$A,0)),"—") -> Pomme rouge brillante
A6: 5688 | B6: Renée l'aubergiste | C6: La taverne des Pendus | D6: 1420 | E6: 61.7 | F6: 52.1 | G6: 159 | H6: =IFERROR(INDEX(Ingrédients!$B:$B,MATCH(G6,Ingrédients!$A:$A,0)),"—") -> Eau de source
A7: 6741 | B7: Norman l'aubergiste | C7: Fossoyeuse | D7: 1458 | E7: 67.6 | F7: 38.1 | G7: 159 | H7: =IFERROR(INDEX(Ingrédients!$B:$B,MATCH(G7,Ingrédients!$A:$A,0)),"—") -> Eau de source
A8: 6741 | B8: Norman l'aubergiste | C8: Fossoyeuse | D8: 1458 | E8: 67.6 | F8: 38.1 | G8: 1179 | H8: =IFERROR(INDEX(Ingrédients!$B:$B,MATCH(G8,Ingrédients!$A:$A,0)),"—") -> Lait glacé
A9: 6741 | B9: Norman l'aubergiste | C9: Fossoyeuse | D9: 1458 | E9: 67.6 | F9: 38.1 | G9: 1205 | H9: =IFERROR(INDEX(Ingrédients!$B:$B,MATCH(G9,Ingrédients!$A:$A,0)),"—") -> Jus de melon
A10: 6741 | B10: Norman l'aubergiste | C10: Fossoyeuse | D10: 1458 | E10: 67.6 | F10: 38.1 | G10: 1708 | H10: =IFERROR(INDEX(Ingrédients!$B:$B,MATCH(G10,Ingrédients!$A:$A,0)),"—") -> Nectar sucré
A11: 6741 | B11: Norman l'aubergiste | C11: Fossoyeuse | D11: 1458 | E11: 67.6 | F11: 38.1 | G11: 1645 | H11: =IFERROR(INDEX(Ingrédients!$B:$B,MATCH(G11,Ingrédients!$A:$A,0)),"—") -> Jus de baie lunaire
A12: 6741 | B12: Norman l'aubergiste | C12: Fossoyeuse | D12: 1458 | E12: 67.6 | F12: 38.1 | G12: 8766 | H12: =IFERROR(INDEX(Ingrédients!$B:$B,MATCH(G12,Ingrédients!$A:$A,0)),"—") -> Soupe de rosée matinale
A13: 4555 | B13: Eleanor Rusk | C13: Fossoyeuse | D13: 1458 | E13: 69.1 | F13: 48.5 | G13: 159 | H13: =IFERROR(INDEX(Ingrédients!$B:$B,MATCH(G13,Ingrédients!$A:$A,0)),"—") -> Eau de source
... A30: 4561 | B30: Daniel Bartlett | C30: Fossoyeuse | D30: 1458 | E30: 64.2 | F30: 37.8 | G30: 3713 | H30: =IFERROR(INDEX(Ingrédients!$B:$B,MATCH(G30,Ingrédients!$A:$A,0)),"—") -> Epices apaisantes
A72: Position = celle du joueur pendant l'échange (approximative). Une ligne par marchand et par composant. mapID = identifiant de carte du jeu (plus fiable que le nom de zone, qui dépend de la langue).

Sheet Marchands_recettes
A1: id_PNJ | B1: Marchand | C1: Zone (client FR) | D1: mapID | E1: X (%) | F1: Y (%) | G1: id_objet_recette | H1: Objet vendu | I1: id_recette (onglet Recettes) | J1: Recette cuisinée | K1: Origine
A2: 2118 | B2: Abigail Shiel | C2: Clairières de Tirisfal | D2: 1420 | E2: 61 | F2: 52.4 | G2: 12226 | H2: Recette : Aile de chauve-souris croustillante | I2: 12224 | J2: =IFERROR(INDEX(Recettes!$C:$C,MATCH(I2,Recettes!$A:$A,0)),"—") -> Aile de chauve-souris croustillante | K2: Relevé en jeu (bêta)
A3: 3550 | B3: Martine Tramblay | C3: Clairières de Tirisfal | D3: 1420 | E3: 65.9 | F3: 59.6 | G3: 6325 | H3: Recette : Goujon brillant | I3: 6290 | J3: =IFERROR(INDEX(Recettes!$C:$C,MATCH(I3,Recettes!$A:$A,0)),"—") -> Goujon brillant | K3: Relevé en jeu (bêta)
A4: 3550 | B4: Martine Tramblay | C4: Clairières de Tirisfal | D4: 1420 | E4: 65.9 | F4: 59.6 | G4: 6326 | H4: Recette : Maquereau ombré | I4: 787 | J4: =IFERROR(INDEX(Recettes!$C:$C,MATCH(I4,Recettes!$A:$A,0)),"—") -> Maquereau ombré | K4: Relevé en jeu (bêta)
A5: 3556 | B5: Andrew Hilbert | C5: Forêt des Pins argentés | D5: 1421 | E5: 43.2 | F5: 40.7 | G5: 6892 | H5: Recette : Viande d'ours fumée | I5: 6890 | J5: =IFERROR(INDEX(Recettes!$C:$C,MATCH(I5,Recettes!$A:$A,0)),"—") -> Viande d'ours fumée | K5: Web (QuestieDB, Classic), à confirmer en jeu : id de l'objet recette et position importés de QuestieDB
A6: 2664 | B6: Kelsey Yance | C6: Vallée de Strangleronce | D6: 1434 | E6: 28.2 | F6: 74.3 | G6: 13940 | H6: Recette : Barracuda luisant cuit | I6: 13927 | J6: =IFERROR(INDEX(Recettes!$C:$C,MATCH(I6,Recettes!$A:$A,0)),"—") -> Barracuda luisant cuit | K6: Web (QuestieDB, Classic), à confirmer en jeu : id de l'objet recette et position importés de QuestieDB
A46: Position = celle du joueur pendant l'échange (approximative). Une ligne par recette vendue. Cellules jaune clair = position non relevée.

Sheet Rangs_métier
A1: Rang | B1: Compétence min | C1: Compétence max | D1: Niveau perso requis | E1: Remarque
A2: Apprenti | B2: 1 | C2: 50 | E2: Aucun niveau requis dans la bêta d'après le guide source (apprentissage possible dès la création)
A3: Compagnon | B3: 50 | C3: 150 | D3: 10 | E3: Requiert 50 en Cuisine et niveau 10 (guide source)
A4: Expert | B4: 150 | C4: 225 | E4: Niveau perso requis non récupéré
A5: Artisan | B5: 225 | C5: 300 | E5: Non testé par l'auteur du guide (plafond de niveau de la bêta) ; le jeu compte des recettes jusqu'à 365

Sheet Sources_données
A1: Donnée | B1: Source | C1: URL | D1: Date de consultation
A2: Recettes, composants, niveaux de couleur | B2: SeeMeta — Recettes Cuisine WoW Forever (bêta 1.60.1) | C2: https://seemeta.com/fr/wow-forever/professions/cooking | D2: 2026-10-07
A3: Rangs de métier, niveaux requis | B3: WoW Professions — Cooking Leveling Guide 1-300 | C3: https://www.wow-professions.com/forever/cooking-leveling-guide | D3: 2026-10-07
A4: Smoothies (vendeurs de l'Azeroth Commerce Authority) | B4: Warcraft Tavern — New Cooking Recipes | C4: https://www.warcrafttavern.com/forever/news/new-cooking-recipes-for-world-of-warcraft-forever/ | D4: 2026-10-07
A5: Zones, niveaux et monstres par ingrédient | B5: Wowhead Classic — Best Cooking Ingredient Farming Spots (1.15.8, màj 2024) | C5: https://www.wowhead.com/classic/guide/best-cooking-meat-farming-locations-classic-wow | D5: 2026-10-07
A6: Zones de pêche, compétence requise, taux de prise | B6: Wowhead Classic — Best Fishing Farming Spots (1.15.8, màj 2025) | C6: https://www.wowhead.com/classic/guide/best-fishing-pools-farming-locations-classic-wow | D6: 2026-10-07
A7: Furie du loch crue (Loch Modan) | B7: Warcraft Wiki — Fishing items | C7: https://warcraft.wiki.gg/wiki/Fishing_items | D7: 2026-10-07
A8: Marchands de composants (relevés en jeu) | B8: Addon CuisineMarchands, test dans les Clairières de Tirisfal (bêta) | C8: Fichier SavedVariables CuisineMarchands.lua | D8: 2026-10-07
A9: Épices vendues par les marchands de cuisine | B9: Warcraft Tavern — Cooking guide Forever | C9: https://www.warcrafttavern.com/forever/guides/cooking/ | D9: 2026-10-07
A10: Marchands et recettes vendues (Classic, à confirmer en jeu) | B10: Warcraft Wiki — pages des PNJ et listes de recettes de cuisine | C10: https://warcraft.wiki.gg/wiki/List_of_Apprentice_Cooking_Recipes | D10: 2026-10-08
A11: Maîtres de cuisine et coordonnées | B11: Overgear et Icy Veins — guides de cuisine WoW Classic | C11: https://overgear.com/guides/wow-classic/cooking/ | D11: 2026-10-08
A12: Maîtres, quêtes, vendeurs de recettes, niveaux orange, butin des nouveaux ingrédients | B12: QuestieDB (github.com/Questie/QuestieDB), données Classic Era reprojetées sur Forever - licence GPL v3 à confirmer | C12: https://github.com/Questie/QuestieDB | D12: 2026-10-10
A13: Recettes, composants et paliers (recoupement) | B13: AtlasLoot Classic (github.com/Hoizame/AtlasLootClassic), GPL v2 | C13: https://github.com/Hoizame/AtlasLootClassic | D13: 2026-10-10

Sheet Web_marchands
A1: PNJ (EN) | B1: id_PNJ (Forever) | C1: Zone | D1: Position (x / y) | E1: Faction | F1: Article | G1: Type | H1: Prix (source) | I1: Source (URL) | J1: Période indiquée par la source | K1: Relevé en jeu (Forever) | L1: Remarque
A2: Abigail Shiel | B2: 2118 | C2: Brill, Clairières de Tirisfal | D2: 61 / 52 | E2: Horde | F2: Mild Spices (épices douces) | G2: composant | H2: 10c (x5) | I2: https://warcraft.wiki.gg/wiki/Abigail_Shiel | J2: Actuel | K2: Oui | L2: Confirmé en jeu (61 / 52,4)
A3: Abigail Shiel | B3: 2118 | C3: Brill, Clairières de Tirisfal | D3: 61 / 52 | E3: Horde | F3: Simple Flour (farine simple) | G3: composant | H3: 25c (x5) | I3: https://warcraft.wiki.gg/wiki/Abigail_Shiel | J3: Ajouté au patch 2.0.3 | K3: Non | L3: Absent du relevé en jeu : cohérent avec un client sans le contenu de 2.0.3
A4: Abigail Shiel | B4: 2118 | C4: Brill, Clairières de Tirisfal | D4: 61 / 52 | E4: Horde | F4: Recipe: Crispy Bat Wing | G4: recette | H4: 25c | I4: https://warcraft.wiki.gg/wiki/Abigail_Shiel | J4: Classic | K4: Oui | L4: Recette de la quête 1 (objet 12226)
A5: Andrew Hilbert | C5: Sepulcher, Silverpine Forest | D5: 43 / 41 | E5: Horde | F5: Hot Spices (épices fortes) | G5: composant | H5: 40c | I5: https://warcraft.wiki.gg/wiki/Andrew_Hilbert | J5: Classic (retiré en 3.1.0) | K5: Non | L5: À relever en jeu
A6: Andrew Hilbert | C6: Sepulcher, Silverpine Forest | D6: 43 / 41 | E6: Horde | F6: Mild Spices (épices douces) | G6: composant | H6: 10c (x5) | I6: https://warcraft.wiki.gg/wiki/Andrew_Hilbert | J6: Actuel | K6: Non | L6: À relever en jeu
A7: Andrew Hilbert | C7: Sepulcher, Silverpine Forest | D7: 43 / 41 | E7: Horde | F7: Salt (sel) | G7: composant | H7: 50c | I7: https://warcraft.wiki.gg/wiki/Andrew_Hilbert | J7: Actuel | K7: Non | L7: À relever en jeu
A8: Andrew Hilbert | C8: Sepulcher, Silverpine Forest | D8: 43 / 41 | E8: Horde | F8: Recipe: Smoked Bear Meat | G8: recette | H8: 2s 50c | I8: https://warcraft.wiki.gg/wiki/Andrew_Hilbert | J8: Classic | K8: Non | L8: Recette de la quête 2 : à acheter ici (côté Horde)
A9: Daniel Bartlett | B9: 4561 | C9: Trade Quarter, Undercity (Fossoyeuse) | D9: non indiquée | E9: Horde | F9: Hot Spices (épices fortes) | G9: composant | H9: 40c | I9: https://warcraft.wiki.gg/wiki/Daniel_Bartlett | J9: Classic (retiré en 3.1.0) | K9: Oui | L9: Confirmé en jeu (64,2 / 37,8)
A10: Daniel Bartlett | B10: 4561 | C10: Trade Quarter, Undercity (Fossoyeuse) | D10: non indiquée | E10: Horde | F10: Soothing Spices (épices apaisantes) | G10: composant | H10: 1s 60c | I10: https://warcraft.wiki.gg/wiki/Daniel_Bartlett | J10: Classic (retiré en 3.1.0) | K10: Oui | L10: Confirmé en jeu
A11: Felicia Doan | B11: 4775 | C11: Trade Quarter, Undercity (Fossoyeuse) | D11: non indiquée | E11: Horde | F11: Hot Spices (épices fortes) | G11: composant | H11: 34c (prix de la page) | I11: https://warcraft.wiki.gg/wiki/Felicia_Doan | J11: Classic (retiré en 3.1.0) | K11: Oui | L11: Confirmé en jeu (64,1 / 50,2)
A12: Felicia Doan | B12: 4775 | C12: Trade Quarter, Undercity (Fossoyeuse) | D12: non indiquée | E12: Horde | F12: Soothing Spices (épices apaisantes) | G12: composant | H12: 1s 36c (prix de la page) | I12: https://warcraft.wiki.gg/wiki/Felicia_Doan | J12: Classic (retiré en 3.1.0) | K12: Oui | L12: Confirmé en jeu
A13: Ronald Burch | B13: 4553 | C13: Trade Quarter, Undercity (Fossoyeuse) | D13: non indiquée | E13: Horde | F13: Hot Spices (épices fortes) | G13: composant | H13: 40c | I13: https://warcraft.wiki.gg/wiki/Ronald_Burch | J13: Classic (retiré en 3.1.0) | K13: Non | L13: Marchand de cuisine à visiter : à relever en jeu
A14: Ronald Burch | B14: 4553 | C14: Trade Quarter, Undercity (Fossoyeuse) | D14: non indiquée | E14: Horde | F14: Soothing Spices (épices apaisantes) | G14: composant | H14: 1s 60c | I14: https://warcraft.wiki.gg/wiki/Ronald_Burch | J14: Classic (retiré en 3.1.0) | K14: Non | L14: À relever en jeu
A15: Ronald Burch | B15: 4553 | C15: Trade Quarter, Undercity (Fossoyeuse) | D15: non indiquée | E15: Horde | F15: Mild Spices, Simple Flour, Refreshing Spring Water | G15: composant | H15: 10c / 25c / 5c (x5) | I15: https://warcraft.wiki.gg/wiki/Ronald_Burch | J15: Actuel | K15: Non | L15: Liste de la version actuelle du jeu : à confirmer
A16: Eleanor Rusk | B16: 4555 | C16: Trade Quarter, Undercity (Fossoyeuse) | D16: non indiquée | E16: Horde | F16: Refreshing Spring Water, Ice Cold Milk, Melon Juice, Sweet Nectar, Moonberry Juice, Morning Glory Dew | G16: composant | H16: 5c / 1s25c / 5s / 10s / 20s / 40s (x5) | I16: https://warcraft.wiki.gg/wiki/Eleanor_Rusk | J16: Classic | K16: Oui | L16: Confirmé en jeu (69,1 / 48,5)
A17: Eleanor Rusk | B17: 4555 | C17: Trade Quarter, Undercity (Fossoyeuse) | D17: non indiquée | E17: Horde | F17: Simple Wood (bois simple) | G17: composant | H17: 38c | I17: https://warcraft.wiki.gg/wiki/Eleanor_Rusk | J17: Classic | K17: Oui | L17: Confirmé en jeu
A18: Eleanor Rusk | B18: 4555 | C18: Trade Quarter, Undercity (Fossoyeuse) | D18: non indiquée | E18: Horde | F18: Star Wood (bois d'étoile) | G18: composant | H18: non listé | I18: https://warcraft.wiki.gg/wiki/Eleanor_Rusk | J18: Absent de la page | K18: Oui | L18: Écart : vendu en jeu, absent de la page
A19: Thaddeus Webb | B19: 4617 | C19: Apothecarium, Undercity (Fossoyeuse) | D19: non indiquée | E19: Horde | F19: Simple Wood (bois simple), Star Wood (bois d'étoile) | G19: composant | H19: 38c / 45s | I19: https://warcraft.wiki.gg/wiki/Thaddeus_Webb | J19: Actuel (liste Classic contradictoire) | K19: Oui | L19: Confirmé en jeu (62 / 60,9)
A20: Chef Audrey | C20: Fossoyeuse | D20: 63 / 34,4 | E20: Horde | F20: Refreshing Spring Water, Ice Cold Milk, Melon Juice, Sweet Nectar, Moonberry Juice, Morning Glory Dew (+ champignons) | G20: composant | H20: 5c / 1s25c / 5s / 10s / 20s / 40s (x5) | I20: https://warcraft.wiki.gg/wiki/Chef_Audrey | J20: Actuel | K20: Non | L20: À relever en jeu : distinct de Norman l'aubergiste (67,6 / 38,1)
A21: Martine Tramblay | B21: 3550 | C21: Death's Watch Waystation, Clairières de Tirisfal | D21: 66 / 60 | E21: Horde | F21: Recipe: Brilliant Smallfish | G21: recette | H21: 40c | I21: https://warcraft.wiki.gg/wiki/Martine_Tramblay | J21: Non daté | K21: Oui | L21: Confirmé en jeu (65,9 / 59,6), objet 6325
A22: Martine Tramblay | B22: 3550 | C22: Death's Watch Waystation, Clairières de Tirisfal | D22: 66 / 60 | E22: Horde | F22: Recipe: Slitherskin Mackerel | G22: recette | H22: 40c | I22: https://warcraft.wiki.gg/wiki/Martine_Tramblay | J22: Non daté | K22: Oui | L22: Confirmé en jeu, objet 6326
A23: Martine Tramblay | B23: 3550 | C23: Death's Watch Waystation, Clairières de Tirisfal | D23: 66 / 60 | E23: Horde | F23: Couteau de chef (objet 273636) | G23: autre | H23: non listé | I23: https://warcraft.wiki.gg/wiki/Martine_Tramblay | J23: Absent de la page | K23: Oui | L23: Objet propre à Forever : absent des sources web
A24: Xen'to | B24: 3400 | C24: Orgrimmar | D24: non indiquée | E24: Horde | F24: Water, Mild/Hot/Soothing Spices, Simple Flour, Recipe: Smoked Sagefish, Recipe: Sagefish Delight | G24: composant + recette | H24: 10c à 50s | I24: https://wowclassicdb.com/wotlk/npc/3400 | J24: Version WotLK de la base | K24: Non | L24: À relever en jeu
A25: Wulan | C25: Shadowprey Village, Désolace | D25: 26 / 70 | E25: Horde | F25: Expert Cookbook (livre de cuisine de l'expert) | G25: recette | H25: 1g | I25: https://warcraft.wiki.gg/wiki/Wulan | J25: Classic (retiré en 3.1.0) | K25: Non | L25: Livre pour passer au rang Expert
A26: Wulan | C26: Shadowprey Village, Désolace | D26: 26 / 70 | E26: Horde | F26: Hot Spices, Soothing Spices | G26: composant | H26: 40c / 1s 60c | I26: https://warcraft.wiki.gg/wiki/Wulan | J26: Classic (retiré en 3.1.0) | K26: Non | L26: À relever en jeu

Sheet Web_recettes
A1: Recette (EN) | B1: Niveau d'apprentissage | C1: Marchand | D1: Zone | E1: Position | F1: Faction | G1: Prix | H1: Source (URL)
A2: Brilliant Smallfish | B2: 1 | C2: Martine Tramblay | D2: Clairières de Tirisfal | E2: 66 / 60 | F2: Horde | G2: 40c | H2: https://warcraft.wiki.gg/wiki/Martine_Tramblay
A3: Slitherskin Mackerel | B3: 1 | C3: Martine Tramblay | D3: Clairières de Tirisfal | E3: 66 / 60 | F3: Horde | G3: 40c | H3: https://warcraft.wiki.gg/wiki/Martine_Tramblay
A4: Scorpid Surprise | B4: 20 | C4: Grimtak | D4: Razor Hill, Durotar | E4: non indiquée | F4: Horde | G4: 1s 33c | H4: https://warcraft.wiki.gg/wiki/List_of_Apprentice_Cooking_Recipes
A5: Roasted Kodo Meat | B5: 35 | C5: Wunna Darkmane | D5: Bloodhoof Village, Mulgore | E5: non indiquée | F5: Horde | G5: 2s 28c | H5: https://warcraft.wiki.gg/wiki/List_of_Apprentice_Cooking_Recipes
A6: Bat Bites | B6: 50 | C6: Master Chef Mouldier | D6: Tranquillien, Ghostlands | E6: non indiquée | F6: Horde | G6: 4s | H6: https://warcraft.wiki.gg/wiki/List_of_Apprentice_Cooking_Recipes
A7: Strider Stew | B7: 50 | C7: Tari'qa | D7: Crossroads, Northern Barrens | E7: 51,6 / 30 | F7: Horde | G7: 4s 40c | H7: https://warcraft.wiki.gg/wiki/List_of_Apprentice_Cooking_Recipes
A8: Crunchy Spider Surprise | B8: 60 | C8: Master Chef Mouldier | D8: Tranquillien, Ghostlands | E8: non indiquée | F8: Horde | G8: 4s | H8: https://warcraft.wiki.gg/wiki/List_of_Apprentice_Cooking_Recipes
A9: Crispy Lizard Tail | B9: 100 | C9: Tari'qa | D9: Crossroads, Northern Barrens | E9: 51,6 / 30 | F9: Horde | G9: 4s | H9: https://warcraft.wiki.gg/wiki/List_of_Journeyman_Cooking_Recipes
A10: Lean Wolf Steak | B10: 125 | C10: Zargh | D10: Crossroads, Northern Barrens | E10: 52,6 / 29,8 | F10: Horde | G10: 16s | H10: https://warcraft.wiki.gg/wiki/List_of_Journeyman_Cooking_Recipes
A11: Hot Lion Chops | B11: 125 | C11: Zargh | D11: Crossroads, Northern Barrens | E11: 52,6 / 29,8 | F11: Horde | G11: 18s | H11: https://warcraft.wiki.gg/wiki/List_of_Journeyman_Cooking_Recipes
A12: Curiously Tasty Omelet | B12: 130 | C12: Keena | D12: Hammerfall, Arathi Highlands | E12: 74 / 32,6 | F12: Horde | G12: 16s | H12: https://warcraft.wiki.gg/wiki/List_of_Journeyman_Cooking_Recipes
... A29: Expert Cookbook (rang Expert) | B29: 125 | C29: Wulan | D29: Shadowprey Village, Désolace | E29: 26 / 70 | F29: Horde | G29: 1g | H29: https://warcraft.wiki.gg/wiki/Wulan

Sheet Web_maitres
A1: Maître de cuisine | B1: Zone | C1: Position | D1: Faction | E1: Source (URL)
A2: Eunice Burch | B2: Fossoyeuse | C2: 62 / 44 | D2: Horde | E2: https://overgear.com/guides/wow-classic/cooking/
A3: Aska Mistrunner | B3: Pitons-du-Tonnerre | C3: 51 / 52 | D3: Horde | E3: https://overgear.com/guides/wow-classic/cooking/
A4: Zamja | B4: Orgrimmar | C4: 57 / 53 | D4: Horde | E4: https://overgear.com/guides/wow-classic/cooking/
A5: Pyall Silentstride | B5: Mulgore | C5: 45 / 57 | D5: Horde | E5: https://overgear.com/guides/wow-classic/cooking/
A6: Mudduk | B6: Stranglethorn Vale | C6: 37 / 49 | D6: Horde | E6: https://overgear.com/guides/wow-classic/cooking/
A7: Duhng | B7: Tarides | C7: non indiquée | D7: Horde | E7: https://www.icy-veins.com/wow-classic/classic-cooking-profession-guide

Sheet QDB_Maitres
A1: ID PNJ | B1: Maître (FR) | C1: Titre (FR) | D1: Titre (EN) | E1: Zone | F1: Coordonnées | G1: Faction | H1: Niveau
